<?xml version="1.0"?>
<!--
  Humanoid Torso URDF
  A simplified humanoid torso with one arm for learning URDF concepts.

  Validate with: check_urdf humanoid_torso.urdf
  Visualize with: urdf_to_graphviz humanoid_torso.urdf
-->
<robot name="humanoid_torso">

  <!-- Base Link: Torso -->
  <link name="torso_link">
    <visual>
      <geometry>
        <box size="0.4 0.2 0.6"/>
      </geometry>
      <material name="gray">
        <color rgba="0.5 0.5 0.5 1.0"/>
      </material>
    </visual>
    <collision>
      <geometry>
        <box size="0.4 0.2 0.6"/>
      </geometry>
    </collision>
    <inertial>
      <mass value="10.0"/>
      <inertia ixx="0.5" ixy="0" ixz="0" iyy="0.5" iyz="0" izz="0.2"/>
    </inertial>
  </link>

  <!-- Right Shoulder Joint -->
  <joint name="right_shoulder_joint" type="revolute">
    <parent link="torso_link"/>
    <child link="right_upper_arm_link"/>
    <origin xyz="0.25 0 0.25" rpy="0 0 0"/>
    <axis xyz="1 0 0"/>
    <limit lower="-3.14" upper="3.14" effort="50" velocity="2.0"/>
  </joint>

  <!-- Right Upper Arm -->
  <link name="right_upper_arm_link">
    <visual>
      <origin xyz="0 0 -0.15" rpy="0 0 0"/>
      <geometry>
        <cylinder radius="0.04" length="0.3"/>
      </geometry>
      <material name="blue">
        <color rgba="0.2 0.2 0.8 1.0"/>
      </material>
    </visual>
    <collision>
      <origin xyz="0 0 -0.15" rpy="0 0 0"/>
      <geometry>
        <cylinder radius="0.04" length="0.3"/>
      </geometry>
    </collision>
    <inertial>
      <mass value="2.0"/>
      <inertia ixx="0.01" ixy="0" ixz="0" iyy="0.01" iyz="0" izz="0.005"/>
    </inertial>
  </link>

  <!-- Right Elbow Joint -->
  <joint name="right_elbow_joint" type="revolute">
    <parent link="right_upper_arm_link"/>
    <child link="right_forearm_link"/>
    <origin xyz="0 0 -0.3" rpy="0 0 0"/>
    <axis xyz="1 0 0"/>
    <limit lower="0" upper="2.35" effort="30" velocity="2.0"/>
  </joint>

  <!-- Right Forearm -->
  <link name="right_forearm_link">
    <visual>
      <origin xyz="0 0 -0.125" rpy="0 0 0"/>
      <geometry>
        <cylinder radius="0.035" length="0.25"/>
      </geometry>
      <material name="blue">
        <color rgba="0.2 0.2 0.8 1.0"/>
      </material>
    </visual>
    <collision>
      <origin xyz="0 0 -0.125" rpy="0 0 0"/>
      <geometry>
        <cylinder radius="0.035" length="0.25"/>
      </geometry>
    </collision>
    <inertial>
      <mass value="1.5"/>
      <inertia ixx="0.008" ixy="0" ixz="0" iyy="0.008" iyz="0" izz="0.003"/>
    </inertial>
  </link>

</robot>
